<mujoco>
    <option gravity="0 0 -9.81">
        <flag contact="disable"/>
    </option>
    <worldbody>
        <light diffuse="0 0 0" pos="0 0 10" dir="0 0 -1"/>
        <!--geom type="plane" size="2.25 2.25 0.01" rgba="1 1 1 1"/-->
        <body name="b1" pos="0 0 0" euler="0 0 0">
            <joint name="j0" type="hinge" axis="0 1 0" pos="0 0 0"/>
            <geom type="box" pos="0 0 -.5" euler="0 0 0" size=".02 .02 .5"/>
            <body name="b2" pos="0 0 -1" euler="0 0 0">
                <joint name="j1" type="hinge" axis="0 1 0" pos="0 0 0"/>
                <geom type="box" pos="0 0 -.5" euler="0 0 0" size=".02 .02 .5"/>
                <body name="b3" pos="0 0 -1" euler="0 0 0" />
            </body>
        </body>

        <body name="marker1" pos="0 1 0" euler="0 0 0">
            <!--geom type="sphere" pos="0 0 0" size=".02" rgba='1 0 0 1' /-->
            <body name="marker2" pos="0 0 0" euler="0 0 0">
                <geom type="sphere" pos="0 0 0" size=".02" rgba='1 0 0 1' />
            </body>
            <body name="marker3" pos="0 0 0" euler="0 0 0">
                <geom type="sphere" pos="0 0 0" size=".02" rgba='1 0 0 1' />
            </body>
            <body name="marker4" pos="0 0 0" euler="0 0 0">
                <geom type="sphere" pos="0 0 0" size=".02" rgba='1 0 0 1' />
            </body>
            <body name="marker5" pos="0 0 0" euler="0 0 0">
                <geom type="sphere" pos="0 0 0" size=".02" rgba='1 0 0 1' />
            </body>
            <body name="marker6" pos="0 0 0" euler="0 0 0">
                <geom type="sphere" pos="0 0 0" size=".02" rgba='1 0 0 1' />
            </body>
            <body name="marker7" pos="0 0 0" euler="0 0 0">
                <geom type="sphere" pos="0 0 0" size=".02" rgba='1 0 0 1' />
            </body>
        </body>
    </worldbody>
    <actuator>
        <!--position name="position_servo" joint="j0" kp="100" kv="10"/-->
    </actuator>
</mujoco>