<mujoco>
    <option gravity="0 0 -9.81">
        <flag contact="disable"/>
    </option>
    <worldbody>
        <light diffuse="0 0 0" pos="0 0 10" dir="0 0 -1"/>
        <body name="b1" pos="0 0 0" euler="0 0 0">
            <joint name="j0" type="hinge" axis="0 1 0" pos="0 0 0"/>
            <geom type="box" pos="0 0 -.5" euler="0 0 0" size=".02 .02 .5"/>
            <body name="b2" pos="0 0 -1" euler="0 -30 0">
                <joint name="j1" type="hinge" axis="0 1 0" pos="0 0 0"/>
                <geom type="box" pos="0 0 -.5" euler="0 0 0" size=".02 .02 .5"/>
            </body>
        </body>
        <body name="b3" pos="1 0 0" euler="0 0 0">
            <joint name="j2" type="hinge" axis="0 1 0" pos="0 0 0"/>
            <geom type="box" pos="0 0 -.5" euler="0 0 0" size=".02 .02 .5"/>
            <body name="b4" pos="0 0 -1" euler="0 30 0">
                <joint name="j3" type="hinge" axis="0 1 0" pos="0 0 0"/>
                <geom type="box" pos="0 0 -.5" euler="0 0 0" size=".02 .02 .5"/>
                
                <body name="end" pos="0 0 -1" euler="0 0 0" />
            </body>
        </body>
        
    </worldbody>
    <equality>
        <connect body1="b2" body2="b4" anchor="0 0 -1" active="true" />
    </equality>
    <actuator>
        <position name="aj0" joint="j0" kp="5000" kv="500"/>
        <position name="aj2" joint="j2" kp="5000" kv="500"/>
    </actuator>
</mujoco>