<mujoco>
    <option gravity="0 0 -9.81">
        <flag contact="disable"/>
    </option>
    <actuator>
        <position name="j_a" gear="1" joint="j_a" kp="1000000" dampratio="1" ctrlrange="-3.1415 3.1415" />
        <position name="j_b" gear="1" joint="j_b" kp="1000000" dampratio="1" ctrlrange="-3.1415 3.1415" />
    </actuator>
    <asset>
        <material name="col_blue" rgba="0 0 1 1" />
        <material name="col_green" rgba="0 1 0 1" />
        <material name="col_red" rgba="1 0 0 1" />
        <material name="col_white" rgba="1 1 1 1" />
        <material name="col_la" rgba="0.5 0.7 0.5 1" />
        <material name="col_lb" rgba="0.7 0.5 0.5 1" />
        <material name="col_lc" rgba="0.5 0.5 0.7 1" />
    </asset>
    <worldbody>
        <body name="static" pos="0 0 0">
            <geom type="plane" size="10 10 0.1" pos="0 0 -5" rgba=".9 0 0 1" />
            <geom type="box" pos="0 .9 0" euler="0 0 0" size=".1 .1 .1" material="col_lc" />
            <geom type="box" pos="0 -.9 0" euler="0 0 0" size=".1 .1 .1" material="col_lc" />
        </body>

        <body name="l_prim_a" pos="0 0 0" euler="0 0 0">
            <joint name="j_a" type="hinge" pos="0 0 0" axis="0 1 0" />
            <geom type="cylinder" fromto="0 1 0 0 1.2 0" euler="0 0 0" size=".2" material="col_lb" />
            <body name="left_la_sub1" pos="0 0 0" euler="59.25818585 0 -12">
            <geom type="cylinder" fromto="0 1 0 0 1.1 0" size=".2" material="col_lb" />

            <body name="l_sec_a" pos="0 0 0" euler="0 0 0">
                <joint name="j_prim2sec_a" type="hinge" pos="0 0 0" axis="0 1 0" />
                <geom type="cylinder" fromto="0 1.1 0 0 1.2 0" size=".2" material="col_la" />
                <body name="left_lb_sub1" pos="0 0 0" euler="0 0 -78">
                <geom type="cylinder" fromto="0 1.1 0 0 1.2 0" size=".2" material="col_la" />
                </body>
            </body>
            
            </body>
        </body>

        <body name="l_prim_b" pos="0 0 0" euler="0 0 0">
            <joint name="j_b" type="hinge" pos="0 0 0" axis="0 1 0" />
            <geom type="cylinder" fromto="0 -1 0 0 -1.2 0" euler="0 0 0" size=".2" material="col_lb" />
            <body name="right_la_sub1" pos="0 0 0" euler="-59.25818585 0 12">
            <geom type="cylinder" fromto="0 -1 0 0 -1.1 0" size=".2" material="col_lb" />

            <body name="l_sec_b" pos="0 0 0" euler="0 0 0">
                <joint name="j_prim2sec_b" type="hinge" pos="0 0 0" axis="0 1 0" />
                <geom type="cylinder" fromto="0 -1.1 0 0 -1.2 0" size=".2" material="col_lc" />
                <body name="right_lb_sub1" pos="0 0 0" euler="0 0 78">
                <geom type="cylinder" fromto="0 -1.2 0 0 -1.3 0" size=".2" material="col_lc" />
                </body>
            </body>
            
            </body>
        </body>

        <body name="l_prim_cross" pos="0 0 0">
            <joint name="j_cross" type="hinge" pos="0 0 0" axis="0 1 0" />
            <geom type="box" pos="0 0 0" euler="0 0 0" size=".1 .8 .1" material="col_la" />
            <geom type="box" pos="0 0 0" euler="0 0 0" size=".1 .1 .5" material="col_la" />

            <body name="l_sec_cross" pos="0 0 0">
                <joint name="j_prim2sec_cross" type="hinge" pos="0 0 0" axis="0 0 1" />
                <geom type="box" pos=".4 0 .6" euler="0 0 0" size=".5 .1 .1" material="col_lb" />
                <geom type="box" pos=".4 0 -.6" euler="0 0 0" size=".5 .1 .1" material="col_lb" />
                <geom type="box" pos=".8 0 0" euler="0 0 0" size=".1 .1 .5" material="col_lb" />
                <geom type="cylinder" fromto="0.9 0 0 1.5 0 0" size=".1" material="col_lb" />
                <body name="l_endeffector" pos="1 0 0" euler="0 0 0">
                    <geom type="sphere" pos="0 0 0" euler="0 0 0" size=".05" material="col_lb" mass="0" />
                </body>
            </body>
        </body>

    </worldbody>
    <equality>
        <connect body1="l_sec_cross" body2="l_sec_a" anchor="1.1 0 0" active="true" />
        <connect body1="l_sec_cross" body2="l_sec_b" anchor="1.1 0 0" active="true" />
    </equality>
</mujoco>